Traceback (most recent call last):
  File "/Users/joarteaga/Documents/JAAC/Uninorte/Maest Est Aplicada/3c. VISUALIZACIOÃÅN EN R Y PYTHON/Visualizacion_JA_AP/ProyectoFinal_Python/my-book-files/venv_jupyter/lib/python3.9/site-packages/jupyter_cache/executors/utils.py", line 51, in single_nb_execution
    executenb(
  File "/Users/joarteaga/Documents/JAAC/Uninorte/Maest Est Aplicada/3c. VISUALIZACIOÃÅN EN R Y PYTHON/Visualizacion_JA_AP/ProyectoFinal_Python/my-book-files/venv_jupyter/lib/python3.9/site-packages/nbclient/client.py", line 1093, in execute
    return NotebookClient(nb=nb, resources=resources, km=km, **kwargs).execute()
  File "/Users/joarteaga/Documents/JAAC/Uninorte/Maest Est Aplicada/3c. VISUALIZACIOÃÅN EN R Y PYTHON/Visualizacion_JA_AP/ProyectoFinal_Python/my-book-files/venv_jupyter/lib/python3.9/site-packages/nbclient/util.py", line 84, in wrapped
    return just_run(coro(*args, **kwargs))
  File "/Users/joarteaga/Documents/JAAC/Uninorte/Maest Est Aplicada/3c. VISUALIZACIOÃÅN EN R Y PYTHON/Visualizacion_JA_AP/ProyectoFinal_Python/my-book-files/venv_jupyter/lib/python3.9/site-packages/nbclient/util.py", line 62, in just_run
    return loop.run_until_complete(coro)
  File "/usr/local/Cellar/python@3.9/3.9.8/Frameworks/Python.framework/Versions/3.9/lib/python3.9/asyncio/base_events.py", line 642, in run_until_complete
    return future.result()
  File "/Users/joarteaga/Documents/JAAC/Uninorte/Maest Est Aplicada/3c. VISUALIZACIOÃÅN EN R Y PYTHON/Visualizacion_JA_AP/ProyectoFinal_Python/my-book-files/venv_jupyter/lib/python3.9/site-packages/nbclient/client.py", line 559, in async_execute
    await self.async_execute_cell(
  File "/Users/joarteaga/Documents/JAAC/Uninorte/Maest Est Aplicada/3c. VISUALIZACIOÃÅN EN R Y PYTHON/Visualizacion_JA_AP/ProyectoFinal_Python/my-book-files/venv_jupyter/lib/python3.9/site-packages/nbclient/client.py", line 854, in async_execute_cell
    self._check_raise_for_error(cell, exec_reply)
  File "/Users/joarteaga/Documents/JAAC/Uninorte/Maest Est Aplicada/3c. VISUALIZACIOÃÅN EN R Y PYTHON/Visualizacion_JA_AP/ProyectoFinal_Python/my-book-files/venv_jupyter/lib/python3.9/site-packages/nbclient/client.py", line 756, in _check_raise_for_error
    raise CellExecutionError.from_cell_and_msg(cell, exec_reply_content)
nbclient.exceptions.CellExecutionError: An error occurred while executing the following cell:
------------------
import matplotlib.pyplot as plt
import numpy  as np
import pandas as pd
import seaborn as sns
from datetime import datetime
import plotly.express as px
from plotly.offline import plot as px_off_plot
import altair as alt
alt.renderers.enable('html')
from altair import pipe, limit_rows, to_values
t = lambda data: pipe(data, limit_rows(max_rows=10000), to_values)
alt.data_transformers.register('custom', t)
alt.data_transformers.enable('custom')
------------------

[0;31m---------------------------------------------------------------------------[0m
[0;31mModuleNotFoundError[0m                       Traceback (most recent call last)
[0;32m/var/folders/w2/j_r2nxj526x02wjfw52mqty1h_5b0_/T/ipykernel_87028/1155761131.py[0m in [0;36m<module>[0;34m[0m
[1;32m      6[0m [0;32mimport[0m [0mplotly[0m[0;34m.[0m[0mexpress[0m [0;32mas[0m [0mpx[0m[0;34m[0m[0;34m[0m[0m
[1;32m      7[0m [0;32mfrom[0m [0mplotly[0m[0;34m.[0m[0moffline[0m [0;32mimport[0m [0mplot[0m [0;32mas[0m [0mpx_off_plot[0m[0;34m[0m[0;34m[0m[0m
[0;32m----> 8[0;31m [0;32mimport[0m [0maltair[0m [0;32mas[0m [0malt[0m[0;34m[0m[0;34m[0m[0m
[0m[1;32m      9[0m [0malt[0m[0;34m.[0m[0mrenderers[0m[0;34m.[0m[0menable[0m[0;34m([0m[0;34m'html'[0m[0;34m)[0m[0;34m[0m[0;34m[0m[0m
[1;32m     10[0m [0;32mfrom[0m [0maltair[0m [0;32mimport[0m [0mpipe[0m[0;34m,[0m [0mlimit_rows[0m[0;34m,[0m [0mto_values[0m[0;34m[0m[0;34m[0m[0m

[0;31mModuleNotFoundError[0m: No module named 'altair'
ModuleNotFoundError: No module named 'altair'

